<?xml version="1.0" ?>
<!-- =================================================================================== -->
<!-- |    This document was autogenerated by xacro from rsu_2dof.xacro                 | -->
<!-- |    EDITING THIS FILE BY HAND IS NOT RECOMMENDED                                 | -->
<!-- =================================================================================== -->
<robot name="rsu_2dof">
  <material name="silver">
    <color rgba="0.700 0.700 0.700 1.000"/>
  </material>
  <transmission name="upper_crank_tran">
    <type>transmission_interface/SimpleTransmission</type>
    <joint name="upper_crank">
      <hardwareInterface>hardware_interface/EffortJointInterface</hardwareInterface>
    </joint>
    <actuator name="upper_crank_actr">
      <hardwareInterface>hardware_interface/EffortJointInterface</hardwareInterface>
      <mechanicalReduction>1</mechanicalReduction>
    </actuator>
  </transmission>
  <transmission name="lower_crank_tran">
    <type>transmission_interface/SimpleTransmission</type>
    <joint name="lower_crank">
      <hardwareInterface>hardware_interface/EffortJointInterface</hardwareInterface>
    </joint>
    <actuator name="lower_crank_actr">
      <hardwareInterface>hardware_interface/EffortJointInterface</hardwareInterface>
      <mechanicalReduction>1</mechanicalReduction>
    </actuator>
  </transmission>
  <transmission name="ankle_pitch_tran">
    <type>transmission_interface/SimpleTransmission</type>
    <joint name="ankle_pitch">
      <hardwareInterface>hardware_interface/EffortJointInterface</hardwareInterface>
    </joint>
    <actuator name="ankle_pitch_actr">
      <hardwareInterface>hardware_interface/EffortJointInterface</hardwareInterface>
      <mechanicalReduction>1</mechanicalReduction>
    </actuator>
  </transmission>
  <transmission name="ankle_roll_tran">
    <type>transmission_interface/SimpleTransmission</type>
    <joint name="ankle_roll">
      <hardwareInterface>hardware_interface/EffortJointInterface</hardwareInterface>
    </joint>
    <actuator name="ankle_roll_actr">
      <hardwareInterface>hardware_interface/EffortJointInterface</hardwareInterface>
      <mechanicalReduction>1</mechanicalReduction>
    </actuator>
  </transmission>
  <gazebo>
    <plugin filename="libgazebo_ros_control.so" name="control"/>
  </gazebo>
  <gazebo reference="base_link">
    <material>Gazebo/Silver</material>
    <mu1>0.2</mu1>
    <mu2>0.2</mu2>
    <self_collide>true</self_collide>
    <gravity>true</gravity>
  </gazebo>
  <gazebo reference="upper_crank_1">
    <material>Gazebo/Silver</material>
    <mu1>0.2</mu1>
    <mu2>0.2</mu2>
    <self_collide>true</self_collide>
  </gazebo>
  <gazebo reference="dummy_crank_1">
    <material>Gazebo/Silver</material>
    <mu1>0.2</mu1>
    <mu2>0.2</mu2>
    <self_collide>true</self_collide>
  </gazebo>
  <gazebo reference="ankle_1">
    <material>Gazebo/Silver</material>
    <mu1>0.2</mu1>
    <mu2>0.2</mu2>
    <self_collide>true</self_collide>
  </gazebo>
  <gazebo reference="dummy_foot_1">
    <material>Gazebo/Silver</material>
    <mu1>0.2</mu1>
    <mu2>0.2</mu2>
    <self_collide>true</self_collide>
  </gazebo>
  <gazebo reference="point_c1_1">
    <material>Gazebo/Silver</material>
    <mu1>0.2</mu1>
    <mu2>0.2</mu2>
    <self_collide>true</self_collide>
  </gazebo>
  <gazebo reference="point_c2_1">
    <material>Gazebo/Silver</material>
    <mu1>0.2</mu1>
    <mu2>0.2</mu2>
    <self_collide>true</self_collide>
  </gazebo>
  <gazebo reference="point_u1_1">
    <material>Gazebo/Silver</material>
    <mu1>0.2</mu1>
    <mu2>0.2</mu2>
    <self_collide>true</self_collide>
  </gazebo>
  <gazebo reference="point_u2_1">
    <material>Gazebo/Silver</material>
    <mu1>0.2</mu1>
    <mu2>0.2</mu2>
    <self_collide>true</self_collide>
  </gazebo>
  <gazebo reference="left_TPU_pad_1">
    <material>Gazebo/Silver</material>
    <mu1>0.2</mu1>
    <mu2>0.2</mu2>
    <self_collide>true</self_collide>
  </gazebo>
  <link name="base_link">
    <inertial>
      <origin rpy="0 0 0" xyz="-0.06454735857450085 2.9696553878366672e-05 0.2075971737886553"/>
      <mass value="2.397"/>
      <inertia ixx="0.011389" ixy="-6e-06" ixz="-0.000165" iyy="0.011333" iyz="0.000448" izz="0.001943"/>
    </inertial>
    <visual>
      <origin rpy="0 0 0" xyz="0 0 0"/>
      <geometry>
        <mesh filename="package://rsu_manager/robot_model/meshes/base_link.stl" scale="0.001 0.001 0.001"/>
      </geometry>
      <material name="silver"/>
    </visual>
    <collision>
      <origin rpy="0 0 0" xyz="0 0 0"/>
      <geometry>
        <mesh filename="package://rsu_manager/robot_model/meshes/base_link.stl" scale="0.001 0.001 0.001"/>
      </geometry>
    </collision>
  </link>
  <link name="upper_crank_1">
    <inertial>
      <origin rpy="0 0 0" xyz="-0.006580540837288221 0.006329895030518198 1.445724401047399e-05"/>
      <mass value="0.023"/>
      <inertia ixx="3e-06" ixy="1e-06" ixz="0.0" iyy="7e-06" iyz="-0.0" izz="5e-06"/>
    </inertial>
    <visual>
      <origin rpy="0 0 0" xyz="0.06585 -0.0168 -0.228"/>
      <geometry>
        <mesh filename="package://rsu_manager/robot_model/meshes/upper_crank_1.stl" scale="0.001 0.001 0.001"/>
      </geometry>
      <material name="silver"/>
    </visual>
    <collision>
      <origin rpy="0 0 0" xyz="0.06585 -0.0168 -0.228"/>
      <geometry>
        <mesh filename="package://rsu_manager/robot_model/meshes/upper_crank_1.stl" scale="0.001 0.001 0.001"/>
      </geometry>
    </collision>
  </link>
  <link name="dummy_crank_1">
    <inertial>
      <origin rpy="0 0 0" xyz="-0.006580540835227258 -0.006329895030086477 -1.4457243616844417e-05"/>
      <mass value="0.023"/>
      <inertia ixx="3e-06" ixy="-1e-06" ixz="-0.0" iyy="7e-06" iyz="-0.0" izz="5e-06"/>
    </inertial>
    <visual>
      <origin rpy="0 0 0" xyz="0.06585 0.0162 -0.14"/>
      <geometry>
        <mesh filename="package://rsu_manager/robot_model/meshes/dummy_crank_1.stl" scale="0.001 0.001 0.001"/>
      </geometry>
      <material name="silver"/>
    </visual>
    <collision>
      <origin rpy="0 0 0" xyz="0.06585 0.0162 -0.14"/>
      <geometry>
        <mesh filename="package://rsu_manager/robot_model/meshes/dummy_crank_1.stl" scale="0.001 0.001 0.001"/>
      </geometry>
    </collision>
  </link>
  <link name="ankle_1">
    <inertial>
      <origin rpy="0 0 0" xyz="0.000304888128968131 0.014499818256654359 3.734332731514245e-07"/>
      <mass value="0.032"/>
      <inertia ixx="5e-06" ixy="-0.0" ixz="0.0" iyy="9e-06" iyz="0.0" izz="1e-05"/>
    </inertial>
    <visual>
      <origin rpy="0 0 0" xyz="0.0762 0.0145 -0.058"/>
      <geometry>
        <mesh filename="package://rsu_manager/robot_model/meshes/ankle_1.stl" scale="0.001 0.001 0.001"/>
      </geometry>
      <material name="silver"/>
    </visual>
    <collision>
      <origin rpy="0 0 0" xyz="0.0762 0.0145 -0.058"/>
      <geometry>
        <mesh filename="package://rsu_manager/robot_model/meshes/ankle_1.stl" scale="0.001 0.001 0.001"/>
      </geometry>
    </collision>
  </link>
  <link name="dummy_foot_1">
    <inertial>
      <origin rpy="0 0 0" xyz="-0.01935626168502321 5.034154426653004e-11 -0.034817657252046844"/>
      <mass value="0.334"/>
      <inertia ixx="0.000465" ixy="0.0" ixz="7.7e-05" iyy="0.000788" iyz="-0.0" izz="0.001026"/>
    </inertial>
    <visual>
      <origin rpy="0 0 0" xyz="0.0565 -0.0 -0.058"/>
      <geometry>
        <mesh filename="package://rsu_manager/robot_model/meshes/dummy_foot_1.stl" scale="0.001 0.001 0.001"/>
      </geometry>
      <material name="silver"/>
    </visual>
    <collision>
      <origin rpy="0 0 0" xyz="0.0565 -0.0 -0.058"/>
      <geometry>
        <mesh filename="package://rsu_manager/robot_model/meshes/dummy_foot_1.stl" scale="0.001 0.001 0.001"/>
      </geometry>
    </collision>
  </link>
  <link name="point_c1_1">
    <inertial>
      <origin rpy="0 0 0" xyz="7.239654922774896e-08 5.000057170731487e-07 -9.109231108306304e-08"/>
      <mass value="1.5448781874028438e-08"/>
      <inertia ixx="0.0" ixy="-0.0" ixz="0.0" iyy="0.0" iyz="-0.0" izz="0.0"/>
    </inertial>
    <visual>
      <origin rpy="0 0 0" xyz="0.09585 -0.0398 -0.228066"/>
      <geometry>
        <mesh filename="package://rsu_manager/robot_model/meshes/point_c1_1.stl" scale="0.001 0.001 0.001"/>
      </geometry>
      <material name="silver"/>
    </visual>
    <collision>
      <origin rpy="0 0 0" xyz="0.09585 -0.0398 -0.228066"/>
      <geometry>
        <mesh filename="package://rsu_manager/robot_model/meshes/point_c1_1.stl" scale="0.001 0.001 0.001"/>
      </geometry>
    </collision>
  </link>
  <link name="point_c2_1">
    <inertial>
      <origin rpy="0 0 0" xyz="7.239861758712163e-08 -4.999998896373925e-07 9.109051271605217e-08"/>
      <mass value="1.5448781874028438e-08"/>
      <inertia ixx="0.0" ixy="-0.0" ixz="-0.0" iyy="0.0" iyz="-0.0" izz="0.0"/>
    </inertial>
    <visual>
      <origin rpy="0 0 0" xyz="0.09585 0.0392 -0.139934"/>
      <geometry>
        <mesh filename="package://rsu_manager/robot_model/meshes/point_c2_1.stl" scale="0.001 0.001 0.001"/>
      </geometry>
      <material name="silver"/>
    </visual>
    <collision>
      <origin rpy="0 0 0" xyz="0.09585 0.0392 -0.139934"/>
      <geometry>
        <mesh filename="package://rsu_manager/robot_model/meshes/point_c2_1.stl" scale="0.001 0.001 0.001"/>
      </geometry>
    </collision>
  </link>
  <link name="point_u1_1">
    <inertial>
      <origin rpy="0 0 0" xyz="3.0946079032645457e-13 4.999991201348752e-07 1.3990197889057754e-13"/>
      <mass value="1.5448781874028438e-08"/>
      <inertia ixx="0.0" ixy="0.0" ixz="0.0" iyy="0.0" iyz="0.0" izz="0.0"/>
    </inertial>
    <visual>
      <origin rpy="0 0 0" xyz="0.0965 -0.040667 -0.074"/>
      <geometry>
        <mesh filename="package://rsu_manager/robot_model/meshes/point_u1_1.stl" scale="0.001 0.001 0.001"/>
      </geometry>
      <material name="silver"/>
    </visual>
    <collision>
      <origin rpy="0 0 0" xyz="0.0965 -0.040667 -0.074"/>
      <geometry>
        <mesh filename="package://rsu_manager/robot_model/meshes/point_u1_1.stl" scale="0.001 0.001 0.001"/>
      </geometry>
    </collision>
  </link>
  <link name="point_u2_1">
    <inertial>
      <origin rpy="0 0 0" xyz="3.0923874572152954e-13 -5.000008797551025e-07 -3.97237798210881e-13"/>
      <mass value="1.5448781874028438e-08"/>
      <inertia ixx="0.0" ixy="0.0" ixz="-0.0" iyy="0.0" iyz="0.0" izz="0.0"/>
    </inertial>
    <visual>
      <origin rpy="0 0 0" xyz="0.0965 0.040667 -0.074"/>
      <geometry>
        <mesh filename="package://rsu_manager/robot_model/meshes/point_u2_1.stl" scale="0.001 0.001 0.001"/>
      </geometry>
      <material name="silver"/>
    </visual>
    <collision>
      <origin rpy="0 0 0" xyz="0.0965 0.040667 -0.074"/>
      <geometry>
        <mesh filename="package://rsu_manager/robot_model/meshes/point_u2_1.stl" scale="0.001 0.001 0.001"/>
      </geometry>
    </collision>
  </link>
  <link name="left_TPU_pad_1">
    <inertial>
      <origin rpy="0 0 0" xyz="-0.06025801063712779 0.03499999999999956 -0.004596574659817192"/>
      <mass value="0.136"/>
      <inertia ixx="9.6e-05" ixy="-0.0" ixz="-0.0" iyy="0.000228" iyz="0.0" izz="0.000322"/>
    </inertial>
    <visual>
      <origin rpy="0 0 0" xyz="0.0015 0.035 -0.01"/>
      <geometry>
        <mesh filename="package://rsu_manager/robot_model/meshes/left_TPU_pad_1.stl" scale="0.001 0.001 0.001"/>
      </geometry>
      <material name="silver"/>
    </visual>
    <collision>
      <origin rpy="0 0 0" xyz="0.0015 0.035 -0.01"/>
      <geometry>
        <mesh filename="package://rsu_manager/robot_model/meshes/left_TPU_pad_1.stl" scale="0.001 0.001 0.001"/>
      </geometry>
    </collision>
  </link>
  <joint name="upper_crank" type="continuous">
    <origin rpy="0 0 0" xyz="-0.06585 0.0168 0.228"/>
    <parent link="base_link"/>
    <child link="upper_crank_1"/>
    <axis xyz="-0.0 1.0 -0.0"/>
  </joint>
  <joint name="lower_crank" type="continuous">
    <origin rpy="0 0 0" xyz="-0.06585 -0.0162 0.14"/>
    <parent link="base_link"/>
    <child link="dummy_crank_1"/>
    <axis xyz="0.0 -1.0 0.0"/>
  </joint>
  <joint name="ankle_pitch" type="continuous">
    <origin rpy="0 0 0" xyz="-0.0762 -0.0145 0.058"/>
    <parent link="base_link"/>
    <child link="ankle_1"/>
    <axis xyz="-0.0 1.0 -0.0"/>
  </joint>
  <joint name="ankle_roll" type="continuous">
    <origin rpy="0 0 0" xyz="0.0197 0.0145 0.0"/>
    <parent link="ankle_1"/>
    <child link="dummy_foot_1"/>
    <axis xyz="1.0 0.0 -0.0"/>
  </joint>
  <joint name="rigid_c1" type="fixed">
    <origin rpy="0 0 0" xyz="-0.03 0.023 6.6e-05"/>
    <parent link="upper_crank_1"/>
    <child link="point_c1_1"/>
  </joint>
  <joint name="rigid_c2" type="fixed">
    <origin rpy="0 0 0" xyz="-0.03 -0.023 -6.6e-05"/>
    <parent link="dummy_crank_1"/>
    <child link="point_c2_1"/>
  </joint>
  <joint name="rigid_u1" type="fixed">
    <origin rpy="0 0 0" xyz="-0.04 0.040667 0.016"/>
    <parent link="dummy_foot_1"/>
    <child link="point_u1_1"/>
  </joint>
  <joint name="rigid_u2" type="fixed">
    <origin rpy="0 0 0" xyz="-0.04 -0.040667 0.016"/>
    <parent link="dummy_foot_1"/>
    <child link="point_u2_1"/>
  </joint>
  <joint name="rigid_TPU" type="fixed">
    <origin rpy="0 0 0" xyz="0.055 -0.035 -0.048"/>
    <parent link="dummy_foot_1"/>
    <child link="left_TPU_pad_1"/>
  </joint>
</robot>
